[Wed Sep 10 22:07:42.191597 2014] [:error] [pid 3980] [client 192.168.0.100:49283] mod_wsgi (pid=3980): Exception occurred processing WSGI script '/srv/vhosts/mysite/mysite/wsgi.py'.
[Wed Sep 10 22:07:42.217339 2014] [:error] [pid 3980] [client 192.168.0.100:49283] Traceback (most recent call last):
[Wed Sep 10 22:07:42.217366 2014] [:error] [pid 3980] [client 192.168.0.100:49283]   File "/usr/lib/python2.7/site-packages/django/core/handlers/wsgi.py", line 236, in __call__
[Wed Sep 10 22:07:42.234423 2014] [:error] [pid 3980] [client 192.168.0.100:49283]     self.load_middleware()
[Wed Sep 10 22:07:42.234442 2014] [:error] [pid 3980] [client 192.168.0.100:49283]   File "/usr/lib/python2.7/site-packages/django/core/handlers/base.py", line 45, in load_middleware
[Wed Sep 10 22:07:42.234548 2014] [:error] [pid 3980] [client 192.168.0.100:49283]     for middleware_path in settings.MIDDLEWARE_CLASSES:
[Wed Sep 10 22:07:42.234562 2014] [:error] [pid 3980] [client 192.168.0.100:49283]   File "/usr/lib/python2.7/site-packages/django/conf/__init__.py", line 53, in __getattr__
[Wed Sep 10 22:07:42.241223 2014] [:error] [pid 3980] [client 192.168.0.100:49283]     self._setup(name)
[Wed Sep 10 22:07:42.241244 2014] [:error] [pid 3980] [client 192.168.0.100:49283]   File "/usr/lib/python2.7/site-packages/django/conf/__init__.py", line 48, in _setup
[Wed Sep 10 22:07:42.241265 2014] [:error] [pid 3980] [client 192.168.0.100:49283]     self._wrapped = Settings(settings_module)
[Wed Sep 10 22:07:42.241276 2014] [:error] [pid 3980] [client 192.168.0.100:49283]   File "/usr/lib/python2.7/site-packages/django/conf/__init__.py", line 134, in __init__
[Wed Sep 10 22:07:42.241290 2014] [:error] [pid 3980] [client 192.168.0.100:49283]     raise ImportError("Could not import settings '%s' (Is it on sys.path?): %s" % (self.SETTINGS_MODULE, e))
[Wed Sep 10 22:07:42.241307 2014] [:error] [pid 3980] [client 192.168.0.100:49283] ImportError: Could not import settings 'mysite1.settings' (Is it on sys.path?): No module named mysite1.settings
